<?xml version="1.0" ?>
<sdf version="1.4">
	<model name='gball'>
		<static>1</static>
		<link name='base_footprint'>
			<pose>0 0 0 0 -0 0</pose>
			<inertial>
				<pose>0.000487957 0 0.181407 0 -0 0</pose>
				<mass>97.8957</mass>
				<inertia>
					<ixx>3.91766</ixx>
					<ixy>0.008</ixy>
					<ixz>-0.159941</ixz>
					<iyy>8.51815</iyy>
					<iyz>-0.004</iyz>
					<izz>9.03139</izz>
				</inertia>
			</inertial>
			<collision name='base_footprint_collision'>
				<pose>0 0 0 0 -0 0</pose>
				<geometry>
					<box>
						<size>0.001 0.001 0.001</size>
					</box>
				</geometry>
				<surface>
					<contact>
						<ode />
					</contact>
					<friction>
						<ode />
					</friction>
					<bounce />
				</surface>
				<max_contacts>10</max_contacts>
			</collision>
			<collision name='base_footprint_collision_arm_0_link'>
				<pose>0.1 0 0.555 3.14159 -0 0</pose>
				<geometry>
					<mesh>
						<scale>1 1 1</scale>
						<uri>model://gball/meshes/powerball0.stl</uri>
					</mesh>
				</geometry>
				<surface>
					<contact>
						<ode />
					</contact>
					<friction>
						<ode />
					</friction>
					<bounce />
				</surface>
				<surface>
					<contact>
						<ode />
					</contact>
					<friction>
						<ode />
					</friction>
				</surface>
				<max_contacts>10</max_contacts>
			</collision>
			<collision name='base_footprint_collision_base_link'>
				<pose>0 0 0.18 0 -0 0</pose>
				<geometry>
					<mesh>
						<scale>1 1 1</scale>
						<uri>model://gball/meshes/chassisV6.stl</uri>
					</mesh>
				</geometry>
				<surface>
					<contact>
						<ode />
					</contact>
					<friction>
						<ode />
					</friction>
					<bounce />
				</surface>
				<surface>
					<contact>
						<ode />
					</contact>
					<friction>
						<ode />
					</friction>
				</surface>
				<max_contacts>10</max_contacts>
			</collision>
			<collision name='base_footprint_collision_imu_link'>
				<pose>0 0 0.4625 0 -0 0</pose>
				<geometry>
					<box>
						<size>0.001 0.001 0.001</size>
					</box>
				</geometry>
				<surface>
					<contact>
						<ode />
					</contact>
					<friction>
						<ode />
					</friction>
					<bounce />
				</surface>
				<max_contacts>10</max_contacts>
			</collision>
			<collision name='base_footprint_collision_left_track'>
				<pose>0 0 0.18 0 -0 0</pose>
				<geometry>
					<mesh>
						<scale>1 1 1</scale>
						<uri>model://gball/meshes/trackV5_l.stl</uri>
					</mesh>
				</geometry>
				<surface>
					<contact>
						<ode />
					</contact>
					<friction>
						<ode />
					</friction>
					<bounce />
				</surface>
				<surface>
					<contact>
						<ode />
					</contact>
					<friction>
						<ode />
					</friction>
				</surface>
				<surface>
					<contact>
						<ode />
					</contact>
					<friction>
						<ode />
					</friction>
				</surface>
				<max_contacts>10</max_contacts>
			</collision>
			<collision name='base_footprint_collision_right_track'>
				<pose>0 0 0.18 0 -0 3.14159</pose>
				<geometry>
					<mesh>
						<scale>1 1 1</scale>
						<uri>model://gball/meshes/trackV5_l.stl</uri>
					</mesh>
				</geometry>
				<surface>
					<contact>
						<ode />
					</contact>
					<friction>
						<ode />
					</friction>
					<bounce />
				</surface>
				<surface>
					<contact>
						<ode />
					</contact>
					<friction>
						<ode />
					</friction>
				</surface>
				<surface>
					<contact>
						<ode />
					</contact>
					<friction>
						<ode />
					</friction>
				</surface>
				<max_contacts>10</max_contacts>
			</collision>
			<visual name='base_footprint_visual'>
				<pose>0 0 0 0 -0 0</pose>
				<geometry>
					<box>
						<size>0.001 0.001 0.001</size>
					</box>
				</geometry>
				<material>
					<script>
						<name>Gazebo/Green</name>
						<uri>__default__</uri>
					</script>
				</material>
			</visual>
			<visual name='base_footprint_visual_arm_0_link'>
				<pose>0.1 0 0.555 3.14159 -0 0</pose>
				<geometry>
					<mesh>
						<scale>1 1 1</scale>
						<uri>model://gball/meshes/powerball0.stl</uri>
					</mesh>
				</geometry>
				<material>
					<script>
						<name>Gazebo/Grey</name>
						<uri>__default__</uri>
					</script>
				</material>
			</visual>
			<visual name='base_footprint_visual_base_link'>
				<pose>0 0 0.18 0 -0 0</pose>
				<geometry>
					<mesh>
						<scale>1 1 1</scale>
						<uri>model://gball/meshes/chassisV6.stl</uri>
					</mesh>
				</geometry>
				<material>
					<script>
						<name>Gazebo/DarkGrey</name>
						<uri>__default__</uri>
					</script>
				</material>
			</visual>
			<visual name='base_footprint_visual_imu_link'>
				<pose>0 0 0.4625 0 -0 0</pose>
				<geometry>
					<box>
						<size>0.001 0.001 0.001</size>
					</box>
				</geometry>
			</visual>
			<visual name='base_footprint_visual_left_track'>
				<pose>0 0 0.18 0 -0 0</pose>
				<geometry>
					<mesh>
						<scale>1 1 1</scale>
						<uri>model://gball/meshes/trackV5_l.stl</uri>
					</mesh>
				</geometry>
				<material>
					<script>
						<name>Gazebo/FlatBlack</name>
						<uri>__default__</uri>
					</script>
				</material>
				<material>
					<script>
						<name>Gazebo/FlatBlack</name>
						<uri>__default__</uri>
					</script>
				</material>
			</visual>
			<visual name='base_footprint_visual_right_track'>
				<pose>0 0 0.18 0 -0 3.14159</pose>
				<geometry>
					<mesh>
						<scale>1 1 1</scale>
						<uri>model://gball/meshes/trackV5_l.stl</uri>
					</mesh>
				</geometry>
				<material>
					<script>
						<name>Gazebo/FlatBlack</name>
						<uri>__default__</uri>
					</script>
				</material>
				<material>
					<script>
						<name>Gazebo/FlatBlack</name>
						<uri>__default__</uri>
					</script>
				</material>
			</visual>
			<velocity_decay>
				<linear>0</linear>
				<angular>0</angular>
			</velocity_decay>
			<velocity_decay>
				<linear>0</linear>
				<angular>0</angular>
			</velocity_decay>
			<velocity_decay>
				<linear>0</linear>
				<angular>0</angular>
			</velocity_decay>
			<velocity_decay>
				<linear>0</linear>
				<angular>0</angular>
			</velocity_decay>
			<sensor name='base_hokuyo_sensor' type='ray'>
				<visualize>0</visualize>
				<update_rate>10</update_rate>
				<ray>
					<scan>
						<horizontal>
							<samples>684</samples>
							<resolution>1</resolution>
							<min_angle>-2.0944</min_angle>
							<max_angle>2.0944</max_angle>
						</horizontal>
					</scan>
					<range>
						<min>0.1</min>
						<max>5</max>
						<resolution>0.001</resolution>
					</range>
					<noise>
						<type>gaussian</type>
						<mean>0</mean>
						<stddev>0.01</stddev>
					</noise>
				</ray>
				<pose>0.49 0 0.41 0 -0 0</pose>
			</sensor>
			<velocity_decay>
				<linear>0</linear>
				<angular>0</angular>
			</velocity_decay>
			<velocity_decay>
				<linear>0</linear>
				<angular>0</angular>
			</velocity_decay>
			<gravity>1</gravity>
			<velocity_decay>
				<linear>0</linear>
				<angular>0</angular>
			</velocity_decay>
			<gravity>1</gravity>
			<velocity_decay>
				<linear>0</linear>
				<angular>0</angular>
			</velocity_decay>
			<self_collide>0</self_collide>
			<kinematic>0</kinematic>
		</link>
		<link name='arm_1_link'>
			<pose>0.1 4.807e-09 0.6447 3.14159 -0 0</pose>
			<inertial>
				<pose>0 0 0 0 -0 0</pose>
				<mass>0.29364</mass>
				<inertia>
					<ixx>0.01</ixx>
					<ixy>0</ixy>
					<ixz>0</ixz>
					<iyy>0.01</iyy>
					<iyz>0</iyz>
					<izz>0.01</izz>
				</inertia>
			</inertial>
			<collision name='arm_1_link_collision'>
				<pose>0 0 0 0 -0 0</pose>
				<geometry>
					<mesh>
						<scale>1 1 1</scale>
						<uri>model://gball/meshes/powerball1.stl</uri>
					</mesh>
				</geometry>
				<surface>
					<contact>
						<ode />
					</contact>
					<friction>
						<ode />
					</friction>
					<bounce />
				</surface>
				<max_contacts>10</max_contacts>
			</collision>
			<visual name='arm_1_link_visual'>
				<pose>0 0 0 0 -0 0</pose>
				<geometry>
					<mesh>
						<scale>1 1 1</scale>
						<uri>model://gball/meshes/powerball1.stl</uri>
					</mesh>
				</geometry>
				<material>
					<script>
						<name>Gazebo/Grey</name>
						<uri>__default__</uri>
					</script>
				</material>
			</visual>
			<gravity>1</gravity>
			<velocity_decay>
				<linear>0</linear>
				<angular>0</angular>
			</velocity_decay>
			<self_collide>0</self_collide>
			<gravity>1</gravity>
			<kinematic>0</kinematic>
		</link>
		<joint name='arm_1_joint' type='revolute'>
			<child>arm_1_link</child>
			<parent>base_footprint</parent>
			<axis>
				<xyz>0 0 1</xyz>
				<limit>
					<lower>-6.28319</lower>
					<upper>6.28319</upper>
					<effort>370</effort>
					<velocity>2</velocity>
				</limit>
				<dynamics>
					<damping>10</damping>
				</dynamics>
			</axis>
		</joint>
		<link name='arm_2_link'>
			<pose>0.1 4.807e-09 0.6447 -1.57079 0 0</pose>
			<inertial>
				<pose>0 0 0 0 -0 0</pose>
				<mass>1.68311</mass>
				<inertia>
					<ixx>0.03</ixx>
					<ixy>0</ixy>
					<ixz>0</ixz>
					<iyy>0.03</iyy>
					<iyz>0</iyz>
					<izz>0.03</izz>
				</inertia>
			</inertial>
			<collision name='arm_2_link_collision'>
				<pose>0 0 0 0 -0 0</pose>
				<geometry>
					<mesh>
						<scale>1 1 1</scale>
						<uri>model://gball/meshes/powerball2.stl</uri>
					</mesh>
				</geometry>
				<surface>
					<contact>
						<ode />
					</contact>
					<friction>
						<ode />
					</friction>
					<bounce />
				</surface>
				<max_contacts>10</max_contacts>
			</collision>
			<visual name='arm_2_link_visual'>
				<pose>0 0 0 0 -0 0</pose>
				<geometry>
					<mesh>
						<scale>1 1 1</scale>
						<uri>model://gball/meshes/powerball2.stl</uri>
					</mesh>
				</geometry>
				<material>
					<ambient>0 0.13 0.28 1</ambient>
					<diffuse>0 0.13 0.28 1</diffuse>
					<specular>0 0.13 0.28 1</specular>
					<emissive>0 0 0 0</emissive>
				</material>
			</visual>
			<gravity>1</gravity>
			<velocity_decay>
				<linear>0</linear>
				<angular>0</angular>
			</velocity_decay>
			<self_collide>0</self_collide>
			<gravity>1</gravity>
			<kinematic>0</kinematic>
		</link>
		<joint name='arm_2_joint' type='revolute'>
			<child>arm_2_link</child>
			<parent>arm_1_link</parent>
			<axis>
				<xyz>0 -1 -4e-06</xyz>
				<limit>
					<lower>-2.0944</lower>
					<upper>2.0944</upper>
					<effort>370</effort>
					<velocity>2</velocity>
				</limit>
				<dynamics>
					<damping>10</damping>
				</dynamics>
			</axis>
		</joint>
		<link name='arm_3_link'>
			<pose>0.098 0 0.996 0 1.570796 -1.570796</pose>
			<inertial>
				<pose>0 0 0 0 -0 0</pose>
				<mass>2.1</mass>
				<inertia>
					<ixx>0.03</ixx>
					<ixy>0</ixy>
					<ixz>0</ixz>
					<iyy>0.03</iyy>
					<iyz>0</iyz>
					<izz>0.03</izz>
				</inertia>
			</inertial>
			<collision name='arm_3_link_collision'>
				<pose>0 0 0 0 -0 0</pose>
				<geometry>
					<mesh>
						<scale>1 1 1</scale>
						<uri>model://gball/meshes/powerball3.stl</uri>
					</mesh>
				</geometry>
				<surface>
					<contact>
						<ode />
					</contact>
					<friction>
						<ode />
					</friction>
					<bounce />
				</surface>
				<max_contacts>10</max_contacts>
			</collision>
			<visual name='arm_3_link_visual'>
				<pose>0 0 0 0 -0 0</pose>
				<geometry>
					<mesh>
						<scale>1 1 1</scale>
						<uri>model://gball/meshes/powerball3.stl</uri>
					</mesh>
				</geometry>
				<material>
					<script>
						<name>Gazebo/Grey</name>
						<uri>__default__</uri>
					</script>
				</material>
			</visual>
			<gravity>1</gravity>
			<velocity_decay>
				<linear>0</linear>
				<angular>0</angular>
			</velocity_decay>
			<self_collide>0</self_collide>
			<gravity>1</gravity>
			<kinematic>0</kinematic>
		</link>
		<joint name='arm_3_joint' type='revolute'>
			<child>arm_3_link</child>
			<parent>arm_2_link</parent>
			<axis>
				<xyz>0 1 1e-06</xyz>
				<limit>
					<lower>-6.28319</lower>
					<upper>6.28319</upper>
					<effort>176</effort>
					<velocity>2</velocity>
				</limit>
				<dynamics>
					<damping>5</damping>
				</dynamics>
			</axis>
		</joint>
		<link name='arm_4_link'>
			<pose>0.098 0 0.996 -1.570796 -1.570796 1.570796</pose>
			<inertial>
				<pose>0 0 0 0 -0 0</pose>
				<mass>1.68311</mass>
				<inertia>
					<ixx>0.03</ixx>
					<ixy>0</ixy>
					<ixz>0</ixz>
					<iyy>0.03</iyy>
					<iyz>0</iyz>
					<izz>0.03</izz>
				</inertia>
			</inertial>
			<collision name='arm_4_link_collision'>
				<pose>0 0 0 0 -0 0</pose>
				<geometry>
					<mesh>
						<scale>1 1 1</scale>
						<uri>model://gball/meshes/powerball4_robotnik.stl</uri>
					</mesh>
				</geometry>
				<surface>
					<contact>
						<ode />
					</contact>
					<friction>
						<ode />
					</friction>
					<bounce />
				</surface>
				<max_contacts>10</max_contacts>
			</collision>
			<visual name='arm_4_link_visual'>
				<pose>0 0 0 0 -0 0</pose>
				<geometry>
					<mesh>
						<scale>1 1 1</scale>
						<uri>model://gball/meshes/powerball4_robotnik.stl</uri>
					</mesh>
				</geometry>
				<material>
					<ambient>0 0.13 0.28 1</ambient>
					<diffuse>0 0.13 0.28 1</diffuse>
					<specular>0 0.13 0.28 1</specular>
					<emissive>0 0 0 0</emissive>
				</material>
			</visual>
			<gravity>1</gravity>
			<velocity_decay>
				<linear>0</linear>
				<angular>0</angular>
			</velocity_decay>
			<self_collide>0</self_collide>
			<gravity>1</gravity>
			<kinematic>0</kinematic>
		</link>
		<joint name='arm_4_joint' type='revolute'>
			<child>arm_4_link</child>
			<parent>arm_3_link</parent>
			<axis>
				<xyz>0 -3e-06 -1</xyz>
				<limit>
					<lower>-2.0944</lower>
					<upper>2.0944</upper>
					<effort>176</effort>
					<velocity>2</velocity>
				</limit>
				<dynamics>
					<damping>5</damping>
				</dynamics>
			</axis>
		</joint>
		<link name='arm_5_link'>
			<pose>0.4593 -0.0098 0.996 -1.570796 0 3.1415</pose>
			<inertial>
				<pose>0 0 0 0 -0 0</pose>
				<mass>0.807</mass>
				<inertia>
					<ixx>0.03</ixx>
					<ixy>0</ixy>
					<ixz>0</ixz>
					<iyy>0.03</iyy>
					<iyz>0</iyz>
					<izz>0.03</izz>
				</inertia>
			</inertial>
			<collision name='arm_5_link_collision'>
				<pose>0 0 0 0 -0 0</pose>
				<geometry>
					<mesh>
						<scale>1 1 1</scale>
						<uri>model://gball/meshes/powerball5.stl</uri>
					</mesh>
				</geometry>
				<surface>
					<contact>
						<ode />
					</contact>
					<friction>
						<ode />
					</friction>
					<bounce />
				</surface>
				<max_contacts>10</max_contacts>
			</collision>
			<visual name='arm_5_link_visual'>
				<pose>0 0 0 0 -0 0</pose>
				<geometry>
					<mesh>
						<scale>1 1 1</scale>
						<uri>model://gball/meshes/powerball5.stl</uri>
					</mesh>
				</geometry>
				<material>
					<script>
						<name>Gazebo/Grey</name>
						<uri>__default__</uri>
					</script>
				</material>
			</visual>
			<gravity>1</gravity>
			<velocity_decay>
				<linear>0</linear>
				<angular>0</angular>
			</velocity_decay>
			<self_collide>0</self_collide>
			<gravity>1</gravity>
			<kinematic>0</kinematic>
		</link>
		<joint name='arm_5_joint' type='revolute'>
			<child>arm_5_link</child>
			<parent>arm_4_link</parent>
			<axis>
				<xyz>3e-06 1 -6e-06</xyz>
				<limit>
					<lower>-6.28319</lower>
					<upper>6.28319</upper>
					<effort>41.6</effort>
					<velocity>2</velocity>
				</limit>
				<dynamics>
					<damping>5</damping>
				</dynamics>
			</axis>
		</joint>
		<link name='arm_6_link'>
			<pose>0.4593 -0.0098 0.996 3.1415 0 0</pose>
			<inertial>
				<pose>0 0 0 0 -0 0</pose>
				<mass>0.819</mass>
				<inertia>
					<ixx>0.01</ixx>
					<ixy>0</ixy>
					<ixz>0</ixz>
					<iyy>0.01</iyy>
					<iyz>0</iyz>
					<izz>0.01</izz>
				</inertia>
			</inertial>
			<collision name='arm_6_link_collision'>
				<pose>0 0 0 0 -0 0</pose>
				<geometry>
					<mesh>
						<scale>1 1 1</scale>
						<uri>model://gball/meshes/powerball6.stl</uri>
					</mesh>
				</geometry>
				<surface>
					<contact>
						<ode />
					</contact>
					<friction>
						<ode />
					</friction>
					<bounce />
				</surface>
				<max_contacts>10</max_contacts>
			</collision>
			<visual name='arm_6_link_visual'>
				<pose>0 0 0 0 -0 0</pose>
				<geometry>
					<mesh>
						<scale>1 1 1</scale>
						<uri>model://gball/meshes/powerball6.stl</uri>
					</mesh>
				</geometry>
				<material>
					<ambient>0 0.13 0.28 1</ambient>
					<diffuse>0 0.13 0.28 1</diffuse>
					<specular>0 0.13 0.28 1</specular>
					<emissive>0 0 0 0</emissive>
				</material>
			</visual>
			<gravity>1</gravity>
			<velocity_decay>
				<linear>0</linear>
				<angular>0</angular>
			</velocity_decay>
			<self_collide>0</self_collide>
			<gravity>1</gravity>
			<kinematic>0</kinematic>
		</link>
		<joint name='arm_6_joint' type='revolute'>
			<child>arm_6_link</child>
			<parent>arm_5_link</parent>
			<axis>
				<xyz>0 3e-06 1</xyz>
				<limit>
					<lower>-2.0944</lower>
					<upper>2.0944</upper>
					<effort>20.1</effort>
					<velocity>2</velocity>
				</limit>
				<dynamics>
					<damping>5</damping>
				</dynamics>
			</axis>
		</joint>
		<link name='projector'>
			<pose>0.4593 -0.0098 1.1 0 0 0</pose>
			<inertial>
				<pose>0 0 0 0 -0 0</pose>
				<mass>2</mass>
				<inertia>
					<ixx>0.01</ixx>
					<ixy>0</ixy>
					<ixz>0</ixz>
					<iyy>0.01</iyy>
					<iyz>0</iyz>
					<izz>0.01</izz>
				</inertia>
			</inertial>
			<collision name='collision'>
				<pose>0 0 0 0 -0 0</pose>
				<geometry>
					<mesh>
						<scale>1 1 1</scale>
						<uri>model://gball/meshes/asus_b1m.stl</uri>
					</mesh>
				</geometry>
				<surface>
					<contact>
						<ode />
					</contact>
					<friction>
						<ode />
					</friction>
					<bounce />
				</surface>
				<max_contacts>10</max_contacts>
			</collision>
			<visual name='visual'>
				<pose>0 0 0 0 -0 0</pose>
				<geometry>
					<mesh>
						<scale>1 1 1</scale>
						<uri>model://gball/meshes/asus_b1m.stl</uri>
					</mesh>
				</geometry>
				<material>
					<script>
						<name>Gazebo/DarkGrey</name>
						<uri>__default__</uri>
					</script>
				</material>
			</visual>
			<gravity>1</gravity>
			<velocity_decay>
				<linear>0</linear>
				<angular>0</angular>
			</velocity_decay>
			<self_collide>0</self_collide>
			<gravity>1</gravity>
			<kinematic>0</kinematic>
		</link>
		<link name='camera_pan_link'>
			<pose>0.18 0 0.45 0 -0 0</pose>
			<inertial>
				<pose>0 0 0 0 -0 0</pose>
				<mass>0.1</mass>
				<inertia>
					<ixx>0.1</ixx>
					<ixy>0</ixy>
					<ixz>0</ixz>
					<iyy>0.1</iyy>
					<iyz>0</iyz>
					<izz>0.1</izz>
				</inertia>
			</inertial>
			<velocity_decay>
				<linear>0</linear>
				<angular>0</angular>
			</velocity_decay>
			<self_collide>0</self_collide>
			<kinematic>0</kinematic>
			<gravity>1</gravity>
		</link>
		<joint name='joint_camera_pan' type='revolute'>
			<child>camera_pan_link</child>
			<parent>base_footprint</parent>
			<axis>
				<xyz>0 0 1</xyz>
				<limit>
					<lower>-1e+16</lower>
					<upper>1e+16</upper>
				</limit>
				<dynamics />
			</axis>
		</joint>
		<link name='camera_tilt_link'>
			<pose>0.18 0 0.45 0 -0 0</pose>
			<inertial>
				<pose>0 0 0 0 -0 0</pose>
				<mass>0.1</mass>
				<inertia>
					<ixx>0.1</ixx>
					<ixy>0</ixy>
					<ixz>0</ixz>
					<iyy>0.1</iyy>
					<iyz>0</iyz>
					<izz>0.1</izz>
				</inertia>
			</inertial>
			<velocity_decay>
				<linear>0</linear>
				<angular>0</angular>
			</velocity_decay>
			<self_collide>0</self_collide>
			<kinematic>0</kinematic>
			<gravity>1</gravity>
		</link>
		<joint name='joint_camera_tilt' type='revolute'>
			<child>camera_tilt_link</child>
			<parent>camera_pan_link</parent>
			<axis>
				<xyz>0 1 0</xyz>
				<limit>
					<lower>-1e+16</lower>
					<upper>1e+16</upper>
				</limit>
				<dynamics />
			</axis>
		</joint>
		
		<!--
		<link name='back_left_wheel'>
			<pose>-0.3 0.265 0.18 0 -0 0</pose>
			<inertial>
				<pose>0 0 0 0 -0 0</pose>
				<mass>4.5</mass>
				<inertia>
					<ixx>0.059</ixx>
					<ixy>0</ixy>
					<ixz>0</ixz>
					<iyy>0.055</iyy>
					<iyz>0</iyz>
					<izz>0.059</izz>
				</inertia>
			</inertial>
			<collision name='back_left_wheel_collision'>
				<pose>0 0 0 0 -0 -3.14159</pose>
				<geometry>
					<mesh>
						<scale>1 1 1</scale>
						<uri>model://gball/meshes/wheel.stl</uri>
					</mesh>
				</geometry>
				<surface>
					<contact>
						<ode>
							<kp>10000</kp>
							<kd>100</kd>
							<max_vel>2</max_vel>
						</ode>
					</contact>
					<friction>
						<ode>
							<mu>2.5</mu>
							<mu2>0.9</mu2>
							<fdir1>1 0 0</fdir1>
						</ode>
					</friction>
					<bounce />
				</surface>
				<max_contacts>10</max_contacts>
			</collision>
			<visual name='back_left_wheel_visual'>
				<pose>0 0 0 0 -0 -3.14159</pose>
				<geometry>
					<mesh>
						<scale>1 1 1</scale>
						<uri>model://gball/meshes/wheel.stl</uri>
					</mesh>
				</geometry>
				<material>
					<script>
						<name>Gazebo/Grey</name>
						<uri>__default__</uri>
					</script>
				</material>
			</visual>
			<gravity>1</gravity>
			<velocity_decay>
				<linear>0</linear>
				<angular>0</angular>
			</velocity_decay>
			<self_collide>0</self_collide>
			<kinematic>0</kinematic>
		</link>
		<joint name='joint_back_left_wheel' type='revolute'>
			<child>back_left_wheel</child>
			<parent>base_footprint</parent>
			<axis>
				<xyz>0 1 0</xyz>
				<limit>
					<lower>-1e+16</lower>
					<upper>1e+16</upper>
				</limit>
				<dynamics />
			</axis>
		</joint>
		<link name='back_right_wheel'>
			<pose>-0.3 -0.265 0.18 0 -0 0</pose>
			<inertial>
				<pose>0 0 0 0 -0 0</pose>
				<mass>4.5</mass>
				<inertia>
					<ixx>0.059</ixx>
					<ixy>0</ixy>
					<ixz>0</ixz>
					<iyy>0.055</iyy>
					<iyz>0</iyz>
					<izz>0.059</izz>
				</inertia>
			</inertial>
			<collision name='back_right_wheel_collision'>
				<pose>0 0 0 0 -0 0</pose>
				<geometry>
					<mesh>
						<scale>1 1 1</scale>
						<uri>model://gball/meshes/wheel.stl</uri>
					</mesh>
				</geometry>
				<surface>
					<contact>
						<ode>
							<kp>10000</kp>
							<kd>100</kd>
							<max_vel>2</max_vel>
						</ode>
					</contact>
					<friction>
						<ode>
							<mu>2.5</mu>
							<mu2>0.9</mu2>
							<fdir1>1 0 0</fdir1>
						</ode>
					</friction>
					<bounce />
				</surface>
				<max_contacts>10</max_contacts>
			</collision>
			<visual name='back_right_wheel_visual'>
				<pose>0 0 0 0 -0 0</pose>
				<geometry>
					<mesh>
						<scale>1 1 1</scale>
						<uri>model://gball/meshes/wheel.stl</uri>
					</mesh>
				</geometry>
				<material>
					<script>
						<name>Gazebo/Grey</name>
						<uri>__default__</uri>
					</script>
				</material>
			</visual>
			<gravity>1</gravity>
			<velocity_decay>
				<linear>0</linear>
				<angular>0</angular>
			</velocity_decay>
			<self_collide>0</self_collide>
			<kinematic>0</kinematic>
		</link>
		<joint name='joint_back_right_wheel' type='revolute'>
			<child>back_right_wheel</child>
			<parent>base_footprint</parent>
			<axis>
				<xyz>0 1 0</xyz>
				<limit>
					<lower>-1e+16</lower>
					<upper>1e+16</upper>
				</limit>
				<dynamics />
			</axis>
		</joint>
		<link name='front_left_wheel'>
			<pose>0.3 0.265 0.18 0 -0 0</pose>
			<inertial>
				<pose>0 0 0 0 -0 0</pose>
				<mass>4.5</mass>
				<inertia>
					<ixx>0.059</ixx>
					<ixy>0</ixy>
					<ixz>0</ixz>
					<iyy>0.055</iyy>
					<iyz>0</iyz>
					<izz>0.059</izz>
				</inertia>
			</inertial>
			<collision name='front_left_wheel_collision'>
				<pose>0 0 0 0 -0 -3.14159</pose>
				<geometry>
					<mesh>
						<scale>1 1 1</scale>
						<uri>model://gball/meshes/wheel.stl</uri>
					</mesh>
				</geometry>
				<surface>
					<contact>
						<ode>
							<kp>10000</kp>
							<kd>100</kd>
							<max_vel>2</max_vel>
						</ode>
					</contact>
					<friction>
						<ode>
							<mu>2.5</mu>
							<mu2>0.9</mu2>
							<fdir1>1 0 0</fdir1>
						</ode>
					</friction>
					<bounce />
				</surface>
				<max_contacts>10</max_contacts>
			</collision>
			<visual name='front_left_wheel_visual'>
				<pose>0 0 0 0 -0 -3.14159</pose>
				<geometry>
					<mesh>
						<scale>1 1 1</scale>
						<uri>model://gball/meshes/wheel.stl</uri>
					</mesh>
				</geometry>
				<material>
					<script>
						<name>Gazebo/Grey</name>
						<uri>__default__</uri>
					</script>
				</material>
			</visual>
			<gravity>1</gravity>
			<velocity_decay>
				<linear>0</linear>
				<angular>0</angular>
			</velocity_decay>
			<self_collide>0</self_collide>
			<kinematic>0</kinematic>
		</link>
		<joint name='joint_front_left_wheel' type='revolute'>
			<child>front_left_wheel</child>
			<parent>base_footprint</parent>
			<axis>
				<xyz>0 1 0</xyz>
				<limit>
					<lower>-1e+16</lower>
					<upper>1e+16</upper>
				</limit>
				<dynamics />
			</axis>
		</joint>
		<link name='front_right_wheel'>
			<pose>0.3 -0.265 0.18 0 -0 0</pose>
			<inertial>
				<pose>0 0 0 0 -0 0</pose>
				<mass>4.5</mass>
				<inertia>
					<ixx>0.059</ixx>
					<ixy>0</ixy>
					<ixz>0</ixz>
					<iyy>0.055</iyy>
					<iyz>0</iyz>
					<izz>0.059</izz>
				</inertia>
			</inertial>
			<collision name='front_right_wheel_collision'>
				<pose>0 0 0 0 -0 0</pose>
				<geometry>
					<mesh>
						<scale>1 1 1</scale>
						<uri>model://gball/meshes/wheel.stl</uri>
					</mesh>
				</geometry>
				<surface>
					<contact>
						<ode>
							<kp>10000</kp>
							<kd>100</kd>
							<max_vel>2</max_vel>
						</ode>
					</contact>
					<friction>
						<ode>
							<mu>2.5</mu>
							<mu2>0.9</mu2>
							<fdir1>1 0 0</fdir1>
						</ode>
					</friction>
					<bounce />
				</surface>
				<max_contacts>10</max_contacts>
			</collision>
			<visual name='front_right_wheel_visual'>
				<pose>0 0 0 0 -0 0</pose>
				<geometry>
					<mesh>
						<scale>1 1 1</scale>
						<uri>model://gball/meshes/wheel.stl</uri>
					</mesh>
				</geometry>
				<material>
					<script>
						<name>Gazebo/Grey</name>
						<uri>__default__</uri>
					</script>
				</material>
			</visual>
			<gravity>1</gravity>
			<velocity_decay>
				<linear>0</linear>
				<angular>0</angular>
			</velocity_decay>
			<self_collide>0</self_collide>
			<kinematic>0</kinematic>
		</link>
		<joint name='joint_front_right_wheel' type='revolute'>
			<child>front_right_wheel</child>
			<parent>base_footprint</parent>
			<axis>
				<xyz>0 1 0</xyz>
				<limit>
					<lower>-1e+16</lower>
					<upper>1e+16</upper>
				</limit>
				<dynamics />
			</axis>
		</joint>
		 -->
		
		<pose>0 0 0.15 0 -0 0</pose>
	</model>
</sdf>
